<sdf version='1.6'>
  <model name='Kwad'>
    <link name='body'>
      <pose frame=''>0 0 0 0 -0 0</pose>
      <inertial>
        <pose frame=''>0 0 0.002661 0 -0 0</pose>
        <mass>0.109</mass>
        <inertia>
          <ixx>0.000202744</ixx>
          <ixy>0</ixy>
          <ixz>0</ixz>
          <iyy>0.000202788</iyy>
          <iyz>0</iyz>
          <izz>0.000290849</izz>
        </inertia>
      </inertial>
      <collision name='body_collision'>
        <pose frame=''>0 0 0 0 -0 0</pose>
        <geometry>
          <box>
            <size>0.01 0.01 0.0015</size>
          </box>
        </geometry>
        <surface>
          <contact>
            <ode/>
          </contact>
          <friction>
            <ode/>
          </friction>
        </surface>
      </collision>
      <collision name='body_fixed_joint_lump__cap_collision_1'>
        <pose frame=''>0 -0.008 0.027 0 -0 0</pose>
        <geometry>
          <box>
            <size>0.008 0.0035 0.001</size>
          </box>
        </geometry>
        <surface>
          <contact>
            <ode/>
          </contact>
          <friction>
            <ode/>
          </friction>
        </surface>
      </collision>
      <collision name='body_fixed_joint_lump__imu_link_collision_2'>
        <pose frame=''>0 0 0.02 0 -0 0</pose>
        <geometry>
          <box>
            <size>0.01 0.01 0.01</size>
          </box>
        </geometry>
        <surface>
          <contact>
            <ode/>
          </contact>
          <friction>
            <ode/>
          </friction>
        </surface>
      </collision>
      <collision name='body_fixed_joint_lump__motor1_collision_3'>
        <pose frame=''>-0.046 -0.046 0 0 -0 0</pose>
        <geometry>
          <box>
            <size>0.0007 0.0007 0.0025</size>
          </box>
        </geometry>
        <surface>
          <contact>
            <ode/>
          </contact>
          <friction>
            <ode/>
          </friction>
        </surface>
      </collision>
      <collision name='body_fixed_joint_lump__guard1_collision_4'>
        <pose frame=''>-0.0655 -0.0655 0.03 -3.14159 -1.57079 2.3562</pose>
        <geometry>
          <box>
            <size>0.0035 0.0035 0.0003</size>
          </box>
        </geometry>
        <surface>
          <contact>
            <ode/>
          </contact>
          <friction>
            <ode/>
          </friction>
        </surface>
      </collision>
      <collision name='body_fixed_joint_lump__motor2_collision_5'>
        <pose frame=''>-0.046 0.046 0 0 -0 0</pose>
        <geometry>
          <box>
            <size>0.0007 0.0007 0.0025</size>
          </box>
        </geometry>
        <surface>
          <contact>
            <ode/>
          </contact>
          <friction>
            <ode/>
          </friction>
        </surface>
      </collision>
      <collision name='body_fixed_joint_lump__guard2_collision_6'>
        <pose frame=''>-0.0655 0.0655 0.03 3.14159 -1.57079 0.785403</pose>
        <geometry>
          <box>
            <size>0.0035 0.0035 0.0003</size>
          </box>
        </geometry>
        <surface>
          <contact>
            <ode/>
          </contact>
          <friction>
            <ode/>
          </friction>
        </surface>
      </collision>
      <collision name='body_fixed_joint_lump__motor3_collision_7'>
        <pose frame=''>0.046 -0.046 0 0 -0 0</pose>
        <geometry>
          <box>
            <size>0.0007 0.0007 0.0025</size>
          </box>
        </geometry>
        <surface>
          <contact>
            <ode/>
          </contact>
          <friction>
            <ode/>
          </friction>
        </surface>
      </collision>
      <collision name='body_fixed_joint_lump__guard3_collision_8'>
        <pose frame=''>0.0655 -0.0655 0.03 3.14159 -1.57079 -2.3562</pose>
        <geometry>
          <box>
            <size>0.0035 0.0035 0.0003</size>
          </box>
        </geometry>
        <surface>
          <contact>
            <ode/>
          </contact>
          <friction>
            <ode/>
          </friction>
        </surface>
      </collision>
      <collision name='body_fixed_joint_lump__motor4_collision_9'>
        <pose frame=''>0.046 0.046 0 0 -0 0</pose>
        <geometry>
          <box>
            <size>0.0007 0.0007 0.0025</size>
          </box>
        </geometry>
        <surface>
          <contact>
            <ode/>
          </contact>
          <friction>
            <ode/>
          </friction>
        </surface>
      </collision>
      <collision name='body_fixed_joint_lump__guard4_collision_10'>
        <pose frame=''>0.0655 0.0655 0.03 3.14159 -1.57079 -0.785403</pose>
        <geometry>
          <box>
            <size>0.0035 0.0035 0.0003</size>
          </box>
        </geometry>
        <surface>
          <contact>
            <ode/>
          </contact>
          <friction>
            <ode/>
          </friction>
        </surface>
      </collision>
      <visual name='body_visual'>
        <pose frame=''>0 0 0 0 -0 0</pose>
        <geometry>
          <mesh>
            <scale>0.01 0.01 0.01</scale>
            <uri>model://fly_bot_cpp/meshes/body.dae</uri>
          </mesh>
        </geometry>
        <material>
          <script>
            <name>Gazebo/DarkGrey</name>
            <uri>file://media/materials/scripts/gazebo.material</uri>
          </script>
        </material>
      </visual>
      <visual name='body_fixed_joint_lump__cap_visual_1'>
        <pose frame=''>0 -0.008 0.027 0 -0 0</pose>
        <geometry>
          <mesh>
            <scale>0.0088 0.0088 0.0088</scale>
            <uri>model://fly_bot_cpp/meshes/cap.dae</uri>
          </mesh>
        </geometry>
        <material>
          <script>
            <name>Gazebo/FlatBlack</name>
            <uri>file://media/materials/scripts/gazebo.material</uri>
          </script>
        </material>
      </visual>
      <visual name='body_fixed_joint_lump__imu_link_visual_2'>
        <pose frame=''>0 0 0.02 0 -0 0</pose>
        <geometry>
          <box>
            <size>0.001 0.001 0.001</size>
          </box>
        </geometry>
        <material>
          <script>
            <uri>__default__</uri>
            <name>__default__</name>
          </script>
        </material>
      </visual>
      <visual name='body_fixed_joint_lump__motor1_visual_3'>
        <pose frame=''>-0.046 -0.046 0 0 -0 0</pose>
        <geometry>
          <mesh>
            <scale>0.01 0.01 0.01</scale>
            <uri>model://fly_bot_cpp/meshes/motors.dae</uri>
          </mesh>
        </geometry>
        <material>
          <script>
            <name>Gazebo/Grey</name>
            <uri>file://media/materials/scripts/gazebo.material</uri>
          </script>
        </material>
      </visual>
      <visual name='body_fixed_joint_lump__guard1_visual_4'>
        <pose frame=''>-0.0655 -0.0655 0.03 -3.14159 -1.57079 2.3562</pose>
        <geometry>
          <mesh>
            <scale>0.03 0.03 0.03</scale>
            <uri>model://fly_bot_cpp/meshes/guard.stl</uri>
          </mesh>
        </geometry>
        <material>
          <script>
            <name>Gazebo/FlatBlack</name>
            <uri>file://media/materials/scripts/gazebo.material</uri>
          </script>
        </material>
      </visual>
      <visual name='body_fixed_joint_lump__motor2_visual_5'>
        <pose frame=''>-0.046 0.046 0 0 -0 0</pose>
        <geometry>
          <mesh>
            <scale>0.01 0.01 0.01</scale>
            <uri>model://fly_bot_cpp/meshes/motors.dae</uri>
          </mesh>
        </geometry>
        <material>
          <script>
            <name>Gazebo/Grey</name>
            <uri>file://media/materials/scripts/gazebo.material</uri>
          </script>
        </material>
      </visual>
      <visual name='body_fixed_joint_lump__guard2_visual_6'>
        <pose frame=''>-0.0655 0.0655 0.03 3.14159 -1.57079 0.785403</pose>
        <geometry>
          <mesh>
            <scale>0.03 0.03 0.03</scale>
            <uri>model://fly_bot_cpp/meshes/guard.stl</uri>
          </mesh>
        </geometry>
        <material>
          <script>
            <name>Gazebo/FlatBlack</name>
            <uri>file://media/materials/scripts/gazebo.material</uri>
          </script>
        </material>
      </visual>
      <visual name='body_fixed_joint_lump__motor3_visual_7'>
        <pose frame=''>0.046 -0.046 0 0 -0 0</pose>
        <geometry>
          <mesh>
            <scale>0.01 0.01 0.01</scale>
            <uri>model://fly_bot_cpp/meshes/motors.dae</uri>
          </mesh>
        </geometry>
        <material>
          <script>
            <name>Gazebo/Grey</name>
            <uri>file://media/materials/scripts/gazebo.material</uri>
          </script>
        </material>
      </visual>
      <visual name='body_fixed_joint_lump__guard3_visual_8'>
        <pose frame=''>0.0655 -0.0655 0.03 3.14159 -1.57079 -2.3562</pose>
        <geometry>
          <mesh>
            <scale>0.03 0.03 0.03</scale>
            <uri>model://fly_bot_cpp/meshes/guard.stl</uri>
          </mesh>
        </geometry>
        <material>
          <script>
            <name>Gazebo/FlatBlack</name>
            <uri>file://media/materials/scripts/gazebo.material</uri>
          </script>
        </material>
      </visual>
      <visual name='body_fixed_joint_lump__motor4_visual_9'>
        <pose frame=''>0.046 0.046 0 0 -0 0</pose>
        <geometry>
          <mesh>
            <scale>0.01 0.01 0.01</scale>
            <uri>model://fly_bot_cpp/meshes/motors.dae</uri>
          </mesh>
        </geometry>
        <material>
          <script>
            <name>Gazebo/Grey</name>
            <uri>file://media/materials/scripts/gazebo.material</uri>
          </script>
        </material>
      </visual>
      <visual name='body_fixed_joint_lump__guard4_visual_10'>
        <pose frame=''>0.0655 0.0655 0.03 3.14159 -1.57079 -0.785403</pose>
        <geometry>
          <mesh>
            <scale>0.03 0.03 0.03</scale>
            <uri>model://fly_bot_cpp/meshes/guard.stl</uri>
          </mesh>
        </geometry>
        <material>
          <script>
            <name>Gazebo/FlatBlack</name>
            <uri>file://media/materials/scripts/gazebo.material</uri>
          </script>
        </material>
      </visual>
      <velocity_decay/>
      <velocity_decay/>
      <velocity_decay/>
      <sensor name='imu_sensor' type='imu'>
        <always_on>1</always_on>
        <update_rate>100</update_rate>
        <visualize>1</visualize>
        <topic>__default_topic__</topic>
        <plugin name='imu_plugin' filename='libgazebo_ros_imu_sensor.so'>
          <bodyName>imu_link</bodyName>
          <topicName>imu</topicName>
          <gaussianNoise>0</gaussianNoise>
          <updateRateHz>10.0</updateRateHz>
          <xyzOffset>0 0 0</xyzOffset>
          <rpyOffset>0 0 0</rpyOffset>
          <frameName>imu_link</frameName>
        </plugin>
        <pose frame=''>0 0 0.02 0 -0 0</pose>
      </sensor>
      <velocity_decay/>
      <velocity_decay/>
      <velocity_decay/>
      <velocity_decay/>
      <velocity_decay/>
      <velocity_decay/>
      <gravity>1</gravity>
      <velocity_decay/>
      <gravity>1</gravity>
      <velocity_decay/>
    </link>
    <link name='prop1'>
      <pose frame=''>-0.046 -0.046 0 0 -0 0</pose>
      <inertial>
        <pose frame=''>0 0 0 0 -0 0</pose>
        <mass>0.05</mass>
        <inertia>
          <ixx>2.7e-07</ixx>
          <ixy>0</ixy>
          <ixz>0</ixz>
          <iyy>1.26e-05</iyy>
          <iyz>0</iyz>
          <izz>1.285e-05</izz>
        </inertia>
      </inertial>
      <collision name='prop1_collision'>
        <pose frame=''>0 0 0.025 0 -0 0</pose>
        <geometry>
          <box>
            <size>0.00055 8e-05 1e-05</size>
          </box>
        </geometry>
        <surface>
          <contact>
            <ode>
              <max_vel>0.0001</max_vel>
              <min_depth>0.0001</min_depth>
            </ode>
          </contact>
          <friction>
            <ode>
              <mu>0.2</mu>
              <mu2>0.2</mu2>
            </ode>
          </friction>
        </surface>
      </collision>
      <visual name='prop1_visual'>
        <pose frame=''>0 0 0.025 0 -0 0</pose>
        <geometry>
          <mesh>
            <scale>0.02 0.02 0.02</scale>
            <uri>model://fly_bot_cpp/meshes/prop1.dae</uri>
          </mesh>
        </geometry>
        <material>
          <script>
            <name>Gazebo/Black</name>
            <uri>file://media/materials/scripts/gazebo.material</uri>
          </script>
        </material>
      </visual>
      <gravity>1</gravity>
      <velocity_decay>
        <linear>0.9</linear>
        <angular>0.9</angular>
      </velocity_decay>
    </link>
    <joint name='joint_body_prop1' type='revolute'>
      <child>prop1</child>
      <parent>body</parent>
      <axis>
        <xyz>0 0 1</xyz>
        <limit>
          <lower>-1e+16</lower>
          <upper>1e+16</upper>
        </limit>
        <dynamics>
          <damping>1</damping>
          <friction>0</friction>
          <spring_reference>0</spring_reference>
          <spring_stiffness>0</spring_stiffness>
        </dynamics>
        <use_parent_model_frame>0</use_parent_model_frame>
      </axis>
    </joint>
    <link name='prop2'>
      <pose frame=''>-0.046 0.046 0 0 -0 0</pose>
      <inertial>
        <pose frame=''>0 0 0 0 -0 0</pose>
        <mass>0.05</mass>
        <inertia>
          <ixx>2.7e-07</ixx>
          <ixy>0</ixy>
          <ixz>0</ixz>
          <iyy>1.26e-05</iyy>
          <iyz>0</iyz>
          <izz>1.285e-05</izz>
        </inertia>
      </inertial>
      <collision name='prop2_collision'>
        <pose frame=''>0 0 0.025 0 -0 0</pose>
        <geometry>
          <box>
            <size>0.00055 8e-05 1e-05</size>
          </box>
        </geometry>
        <surface>
          <contact>
            <ode>
              <max_vel>0.0001</max_vel>
              <min_depth>0.0001</min_depth>
            </ode>
          </contact>
          <friction>
            <ode>
              <mu>0.2</mu>
              <mu2>0.2</mu2>
            </ode>
          </friction>
        </surface>
      </collision>
      <visual name='prop2_visual'>
        <pose frame=''>0 0 0.025 0 -0 0</pose>
        <geometry>
          <mesh>
            <scale>0.02 0.02 0.02</scale>
            <uri>model://fly_bot_cpp/meshes/prop.dae</uri>
          </mesh>
        </geometry>
        <material>
          <script>
            <name>Gazebo/Black</name>
            <uri>file://media/materials/scripts/gazebo.material</uri>
          </script>
        </material>
      </visual>
      <gravity>1</gravity>
      <velocity_decay>
        <linear>0.9</linear>
        <angular>0.9</angular>
      </velocity_decay>
    </link>
    <joint name='joint_body_prop2' type='revolute'>
      <child>prop2</child>
      <parent>body</parent>
      <axis>
        <xyz>0 0 1</xyz>
        <limit>
          <lower>-1e+16</lower>
          <upper>1e+16</upper>
        </limit>
        <dynamics>
          <damping>1</damping>
          <friction>0</friction>
          <spring_reference>0</spring_reference>
          <spring_stiffness>0</spring_stiffness>
        </dynamics>
        <use_parent_model_frame>0</use_parent_model_frame>
      </axis>
    </joint>
    <link name='prop3'>
      <pose frame=''>0.046 -0.046 0 0 -0 0</pose>
      <inertial>
        <pose frame=''>0 0 0 0 -0 0</pose>
        <mass>0.05</mass>
        <inertia>
          <ixx>2.7e-07</ixx>
          <ixy>0</ixy>
          <ixz>0</ixz>
          <iyy>1.26e-05</iyy>
          <iyz>0</iyz>
          <izz>1.285e-05</izz>
        </inertia>
      </inertial>
      <collision name='prop3_collision'>
        <pose frame=''>0 0 0.025 0 -0 0</pose>
        <geometry>
          <box>
            <size>0.00055 8e-05 1e-05</size>
          </box>
        </geometry>
        <surface>
          <contact>
            <ode>
              <max_vel>0.0001</max_vel>
              <min_depth>0.0001</min_depth>
            </ode>
          </contact>
          <friction>
            <ode>
              <mu>0.2</mu>
              <mu2>0.2</mu2>
            </ode>
          </friction>
        </surface>
      </collision>
      <visual name='prop3_visual'>
        <pose frame=''>0 0 0.025 0 -0 0</pose>
        <geometry>
          <mesh>
            <scale>0.02 0.02 0.02</scale>
            <uri>model://fly_bot_cpp/meshes/prop.dae</uri>
          </mesh>
        </geometry>
        <material>
          <script>
            <name>Gazebo/Black</name>
            <uri>file://media/materials/scripts/gazebo.material</uri>
          </script>
        </material>
      </visual>
      <gravity>1</gravity>
      <velocity_decay>
        <linear>0.9</linear>
        <angular>0.9</angular>
      </velocity_decay>
    </link>
    <joint name='joint_body_prop3' type='revolute'>
      <child>prop3</child>
      <parent>body</parent>
      <axis>
        <xyz>0 0 1</xyz>
        <limit>
          <lower>-1e+16</lower>
          <upper>1e+16</upper>
        </limit>
        <dynamics>
          <damping>1</damping>
          <friction>0</friction>
          <spring_reference>0</spring_reference>
          <spring_stiffness>0</spring_stiffness>
        </dynamics>
        <use_parent_model_frame>0</use_parent_model_frame>
      </axis>
    </joint>
    <link name='prop4'>
      <pose frame=''>0.046 0.046 0 0 -0 0</pose>
      <inertial>
        <pose frame=''>0 0 0 0 -0 0</pose>
        <mass>0.05</mass>
        <inertia>
          <ixx>2.7e-07</ixx>
          <ixy>0</ixy>
          <ixz>0</ixz>
          <iyy>1.26e-05</iyy>
          <iyz>0</iyz>
          <izz>1.285e-05</izz>
        </inertia>
      </inertial>
      <collision name='prop4_collision'>
        <pose frame=''>0 0 0.023 0 -0 0</pose>
        <geometry>
          <box>
            <size>0.0055 0.0008 0.0001</size>
          </box>
        </geometry>
        <surface>
          <contact>
            <ode>
              <max_vel>0.0001</max_vel>
              <min_depth>0.0001</min_depth>
            </ode>
          </contact>
          <friction>
            <ode>
              <mu>0.2</mu>
              <mu2>0.2</mu2>
            </ode>
          </friction>
        </surface>
      </collision>
      <visual name='prop4_visual'>
        <pose frame=''>0 0 0.023 0 -0 0</pose>
        <geometry>
          <mesh>
            <scale>0.02 0.02 0.02</scale>
            <uri>model://fly_bot_cpp/meshes/prop.dae</uri>
          </mesh>
        </geometry>
        <material>
          <script>
            <name>Gazebo/Black</name>
            <uri>file://media/materials/scripts/gazebo.material</uri>
          </script>
        </material>
      </visual>
      <gravity>1</gravity>
      <velocity_decay>
        <linear>0.9</linear>
        <angular>0.9</angular>
      </velocity_decay>
    </link>
    <joint name='joint_body_prop4' type='revolute'>
      <child>prop4</child>
      <parent>body</parent>
      <axis>
        <xyz>0 0 1</xyz>
        <limit>
          <lower>-1e+16</lower>
          <upper>1e+16</upper>
        </limit>
        <dynamics>
          <damping>1</damping>
          <friction>0</friction>
          <spring_reference>0</spring_reference>
          <spring_stiffness>0</spring_stiffness>
        </dynamics>
        <use_parent_model_frame>0</use_parent_model_frame>
      </axis>
    </joint>
    <static>0</static>
  </model>
</sdf>
